Workbook

Sheet Sheet1
A1: left(f21,find(" ",f21))
A3: right(f21,len(f21)-find(" ",f21))
A5: cpi = consumer price index
A6: which measures how price change over time

Sheet CPI
A1: Sector | B1: Year | C1: Month | D1: Cereals and products | E1: Meat and fish | F1: Egg | G1: Milk and products | H1: Oils and fats | I1: Fruits | J1: Vegetables | K1: Pulses and products | L1: Sugar and Confectionery | M1: Spices | N1: Non-alcoholic beverages | O1: Prepared meals, snacks, sweets etc. | P1: Food and beverages | Q1: Pan, tobacco and intoxicants | R1: Clothing | S1: Footwear | T1: Clothing and footwear | U1: Housing | V1: Fuel and light | W1: Household goods and services | X1: Health | Y1: Transport and communication | Z1: Recreation and amusement | AA1: Education | AB1: Personal care and effects | AC1: Miscellaneous | AD1: General index
A2: Rural | B2: 2013 | C2: January | D2: 107.5 | E2: 106.3 | F2: 108.1 | G2: 104.9 | H2: 106.1 | I2: 103.9 | J2: 101.9 | K2: 106.1 | L2: 106.8 | M2: 103.1 | N2: 104.8 | O2: 106.7 | P2: 105.5 | Q2: 105.1 | R2: 106.5 | S2: 105.8 | T2: 106.4 | U2: NA | V2: 105.5 | W2: 104.8 | X2: 104 | Y2: 103.3 | Z2: 103.4 | AA2: 103.8 | AB2: 104.7 | AC2: 104 | AD2: 105.1
A3: Urban | B3: 2013 | C3: January | D3: 110.5 | E3: 109.1 | F3: 113 | G3: 103.6 | H3: 103.4 | I3: 102.3 | J3: 102.9 | K3: 105.8 | L3: 105.1 | M3: 101.8 | N3: 105.1 | O3: 107.9 | P3: 105.9 | Q3: 105.2 | R3: 105.9 | S3: 105 | T3: 105.8 | U3: 100.3 | V3: 105.4 | W3: 104.8 | X3: 104.1 | Y3: 103.2 | Z3: 102.9 | AA3: 103.5 | AB3: 104.3 | AC3: 103.7 | AD3: 104
A4: Rural+Urban | B4: 2013 | C4: January | D4: 108.4 | E4: 107.3 | F4: 110 | G4: 104.4 | H4: 105.1 | I4: 103.2 | J4: 102.2 | K4: 106 | L4: 106.2 | M4: 102.7 | N4: 104.9 | O4: 107.3 | P4: 105.6 | Q4: 105.1 | R4: 106.3 | S4: 105.5 | T4: 106.2 | U4: 100.3 | V4: 105.5 | W4: 104.8 | X4: 104 | Y4: 103.2 | Z4: 103.1 | AA4: 103.6 | AB4: 104.5 | AC4: 103.9 | AD4: 104.6
A5: Rural | B5: 2013 | C5: February | D5: 109.2 | E5: 108.7 | F5: 110.2 | G5: 105.4 | H5: 106.7 | I5: 104 | J5: 102.4 | K5: 105.9 | L5: 105.7 | M5: 103.1 | N5: 105.1 | O5: 107.7 | P5: 106.3 | Q5: 105.6 | R5: 107.1 | S5: 106.3 | T5: 107 | U5: NA | V5: 106.2 | W5: 105.2 | X5: 104.4 | Y5: 103.9 | Z5: 104 | AA5: 104.1 | AB5: 104.6 | AC5: 104.4 | AD5: 105.8
A6: Urban | B6: 2013 | C6: February | D6: 112.9 | E6: 112.9 | F6: 116.9 | G6: 104 | H6: 103.5 | I6: 103.1 | J6: 104.9 | K6: 104.1 | L6: 103.8 | M6: 102.3 | N6: 106 | O6: 109 | P6: 107.2 | Q6: 106 | R6: 106.6 | S6: 105.5 | T6: 106.4 | U6: 100.4 | V6: 105.7 | W6: 105.2 | X6: 104.7 | Y6: 104.4 | Z6: 103.3 | AA6: 103.7 | AB6: 104.3 | AC6: 104.3 | AD6: 104.7
A7: Rural+Urban | B7: 2013 | C7: February | D7: 110.4 | E7: 110.2 | F7: 112.8 | G7: 104.9 | H7: 105.5 | I7: 103.6 | J7: 103.2 | K7: 105.3 | L7: 105.1 | M7: 102.8 | N7: 105.5 | O7: 108.3 | P7: 106.6 | Q7: 105.7 | R7: 106.9 | S7: 106 | T7: 106.8 | U7: 100.4 | V7: 106 | W7: 105.2 | X7: 104.5 | Y7: 104.2 | Z7: 103.6 | AA7: 103.9 | AB7: 104.5 | AC7: 104.4 | AD7: 105.3
A8: Rural | B8: 2013 | C8: March | D8: 110.2 | E8: 108.8 | F8: 109.9 | G8: 105.6 | H8: 106.2 | I8: 105.7 | J8: 101.4 | K8: 105.7 | L8: 105 | M8: 103.3 | N8: 105.6 | O8: 108.2 | P8: 106.6 | Q8: 106.5 | R8: 107.6 | S8: 106.8 | T8: 107.5 | U8: NA | V8: 106.1 | W8: 105.6 | X8: 104.7 | Y8: 104.6 | Z8: 104 | AA8: 104.3 | AB8: 104.3 | AC8: 104.6 | AD8: 106
A9: Urban | B9: 2013 | C9: March | D9: 113.9 | E9: 111.4 | F9: 113.2 | G9: 104.3 | H9: 102.7 | I9: 104.9 | J9: 103.8 | K9: 103.5 | L9: 102.6 | M9: 102.4 | N9: 107 | O9: 109.8 | P9: 107.3 | Q9: 106.8 | R9: 107.2 | S9: 106 | T9: 107 | U9: 100.4 | V9: 106 | W9: 105.7 | X9: 105.2 | Y9: 105.5 | Z9: 103.5 | AA9: 103.8 | AB9: 104.2 | AC9: 104.9 | AD9: 105
A10: Rural+Urban | B10: 2013 | C10: March | D10: 111.4 | E10: 109.7 | F10: 111.2 | G10: 105.1 | H10: 104.9 | I10: 105.3 | J10: 102.2 | K10: 105 | L10: 104.2 | M10: 103 | N10: 106.2 | O10: 108.9 | P10: 106.9 | Q10: 106.6 | R10: 107.4 | S10: 106.5 | T10: 107.3 | U10: 100.4 | V10: 106.1 | W10: 105.6 | X10: 104.9 | Y10: 105.1 | Z10: 103.7 | AA10: 104 | AB10: 104.3 | AC10: 104.7 | AD10: 105.5
A11: Rural | B11: 2013 | C11: April | D11: 110.2 | E11: 109.5 | F11: 106.9 | G11: 106.3 | H11: 105.7 | I11: 108.3 | J11: 103.4 | K11: 105.7 | L11: 104.2 | M11: 103.2 | N11: 106.5 | O11: 108.8 | P11: 107.1 | Q11: 107.1 | R11: 108.1 | S11: 107.4 | T11: 108 | U11: NA | V11: 106.5 | W11: 106.1 | X11: 105.1 | Y11: 104.4 | Z11: 104.5 | AA11: 104.8 | AB11: 102.7 | AC11: 104.6 | AD11: 106.4
A12: Urban | B12: 2013 | C12: April | D12: 114.6 | E12: 113.4 | F12: 106 | G12: 104.7 | H12: 102.1 | I12: 109.5 | J12: 109.7 | K12: 104.6 | L12: 102 | M12: 103.5 | N12: 108.2 | O12: 110.6 | P12: 108.8 | Q12: 108.5 | R12: 107.9 | S12: 106.4 | T12: 107.7 | U12: 100.5 | V12: 106.4 | W12: 106.5 | X12: 105.7 | Y12: 105 | Z12: 104 | AA12: 105.2 | AB12: 103.2 | AC12: 105.1 | AD12: 105.7
A13: Rural+Urban | B13: 2013 | C13: April | D13: 111.6 | E13: 110.9 | F13: 106.6 | G13: 105.7 | H13: 104.4 | I13: 108.9 | J13: 105.5 | K13: 105.3 | L13: 103.5 | M13: 103.3 | N13: 107.2 | O13: 109.6 | P13: 107.7 | Q13: 107.5 | R13: 108 | S13: 107 | T13: 107.9 | U13: 100.5 | V13: 106.5 | W13: 106.3 | X13: 105.3 | Y13: 104.7 | Z13: 104.2 | AA13: 105 | AB13: 102.9 | AC13: 104.8 | AD13: 106.1
... A259: Rural+Urban | B259: 2020 | C259: March | D259: 145.1 | E259: 167 | F259: 148.1 | G259: 151.5 | H259: 131.2 | I259: 142.5 | J259: 157.3 | K259: 141.1 | L259: 113.2 | M259: 153.2 | N259: 136.7 | O259: 159.6 | P259: 148.9 | Q259: 171.2 | R259: 151.2 | S259: 141.9 | T259: 149.8 | U259: 154.5 | V259: 148.9 | W259: 146.4 | X259: 152.3 | Y259: 129.9 | Z259: 143.7 | AA259: 156.1 | AB259: 145.2 | AC259: 143.8 | AD259: 148.6
A260: Rural | B260: 2020 | C260: April | D260: 147.2 | F260: 146.9 | G260: 155.6 | H260: 137.1 | I260: 147.3 | J260: 162.7 | K260: 150.2 | L260: 119.8 | M260: 158.7 | N260: 139.2 | P260: 150.1 | U260: NA | V260: 148.4 | X260: 154.3
A261: Urban | B261: 2020 | C261: April | D261: 151.8 | F261: 151.9 | G261: 155.5 | H261: 131.6 | I261: 152.9 | J261: 180 | K261: 150.8 | L261: 121.2 | M261: 154 | N261: 133.5 | P261: 153.5 | U261: 155.6 | V261: 137.1 | X261: 144.8
A262: Rural+Urban | B262: 2020 | C262: April | D262: 148.7 | F262: 148.8 | G262: 155.6 | H262: 135.1 | I262: 149.9 | J262: 168.6 | K262: 150.4 | L262: 120.3 | M262: 157.1 | N262: 136.8 | P262: 151.4 | U262: 155.6 | V262: 144.1 | X262: 150.7
A263: Rural | B263: 2020 | C263: May | U263: NA
A264: Urban | B264: 2020 | C264: May | U264: NA
A265: Rural+Urban | B265: 2020 | C265: May | U265: NA
A266: Rural | B266: 2020 | C266: June | D266: 148.2 | E266: 190.3 | F266: 149.4 | G266: 153.3 | H266: 138.2 | I266: 143.2 | J266: 148.9 | K266: 150.3 | L266: 113.2 | M266: 159.8 | N266: 142.1 | O266: 161.8 | P266: 152.3 | Q266: 182.4 | R266: 154.7 | S266: 150 | T266: 154.1 | U266: NA | V266: 144.9 | W266: 151.7 | X266: 158.2 | Y266: 141.4 | Z266: 153.2 | AA266: 161.8 | AB266: 151.2 | AC266: 151.7 | AD266: 152.7
A267: Urban | B267: 2020 | C267: June | D267: 152.7 | E267: 197 | F267: 154.6 | G267: 153.4 | H267: 132.9 | I267: 151.8 | J267: 171.2 | K267: 152 | L267: 116.3 | M267: 158.8 | N267: 135.6 | O267: 161.7 | P267: 157 | Q267: 186.7 | R267: 149.1 | S267: 136.6 | T267: 147.2 | U267: 154.7 | V267: 137.1 | W267: 140.4 | X267: 148.1 | Y267: 129.3 | Z267: 144.5 | AA267: 152.5 | AB267: 152.2 | AC267: 142 | AD267: 150.8
A268: Rural+Urban | B268: 2020 | C268: June | D268: 149.6 | E268: 192.7 | F268: 151.4 | G268: 153.3 | H268: 136.3 | I268: 147.2 | J268: 156.5 | K268: 150.9 | L268: 114.2 | M268: 159.5 | N268: 139.4 | O268: 161.8 | P268: 154 | Q268: 183.5 | R268: 152.5 | S268: 144.4 | T268: 151.4 | U268: 154.7 | V268: 141.9 | W268: 146.4 | X268: 154.4 | Y268: 135 | Z268: 148.3 | AA268: 156.4 | AB268: 151.6 | AC268: 147 | AD268: 151.8
A269: Rural | B269: 2020 | C269: July | D269: 148.2 | E269: 190.3 | F269: 149.4 | G269: 153.3 | H269: 138.2 | I269: 143.2 | J269: 148.9 | K269: 150.3 | L269: 113.2 | M269: 159.8 | N269: 142.1 | O269: 161.8 | P269: 152.3 | Q269: 182.4 | R269: 154.7 | S269: 150 | T269: 154.1 | U269: NA | V269: 144.9 | W269: 151.7 | X269: 158.2 | Y269: 141.4 | Z269: 153.2 | AA269: 161.8 | AB269: 151.2 | AC269: 151.7 | AD269: 152.7
A270: Urban | B270: 2020 | C270: July | D270: 152.7 | E270: 197 | F270: 154.6 | G270: 153.4 | H270: 132.9 | I270: 151.8 | J270: 171.2 | K270: 152 | L270: 116.3 | M270: 158.8 | N270: 135.6 | O270: 161.7 | P270: 157 | Q270: 186.7 | R270: 149.1 | S270: 136.6 | T270: 147.2 | U270: 154.7 | V270: 137.1 | W270: 140.4 | X270: 148.1 | Y270: 129.3 | Z270: 144.5 | AA270: 152.5 | AB270: 152.2 | AC270: 142 | AD270: 150.8
A271: Rural+Urban | B271: 2020 | C271: July | D271: 149.6 | E271: 192.7 | F271: 151.4 | G271: 153.3 | H271: 136.3 | I271: 147.2 | J271: 156.5 | K271: 150.9 | L271: 114.2 | M271: 159.5 | N271: 139.4 | O271: 161.8 | P271: 154 | Q271: 183.5 | R271: 152.5 | S271: 144.4 | T271: 151.4 | U271: 154.7 | V271: 141.9 | W271: 146.4 | X271: 154.4 | Y271: 135 | Z271: 148.3 | AA271: 156.4 | AB271: 151.6 | AC271: 147 | AD271: 151.8
A272: Rural | B272: 2020 | C272: August | D272: 147.6 | E272: 187.2 | F272: 148.4 | G272: 153.3 | H272: 139.8 | I272: 146.9 | J272: 171 | K272: 149.9 | L272: 114.2 | M272: 160 | N272: 143.5 | O272: 161.5 | P272: 155.3 | Q272: 180.9 | R272: 155.1 | S272: 149.3 | T272: 154.3 | U272: NA | V272: 145.8 | W272: 151.9 | X272: 158.8 | Y272: 143.6 | Z272: 152.2 | AA272: 162.7 | AB272: 153.6 | AC272: 153 | AD272: 154.7
A273: Urban | B273: 2020 | C273: August | D273: 151.6 | E273: 197.8 | F273: 154.5 | G273: 153.4 | H273: 133.4 | I273: 154.5 | J273: 191.9 | K273: 151.3 | L273: 116.8 | M273: 160 | N273: 136.5 | O273: 163.3 | P273: 159.9 | Q273: 187.2 | R273: 150 | S273: 135.2 | T273: 147.8 | U273: 155.5 | V273: 138.3 | W273: 144.5 | X273: 148.7 | Y273: 133.9 | Z273: 141.2 | AA273: 155.5 | AB273: 155.2 | AC273: 144.8 | AD273: 152.9
A274: Rural+Urban | B274: 2020 | C274: August | D274: 148.9 | E274: 190.9 | F274: 150.8 | G274: 153.3 | H274: 137.4 | I274: 150.4 | J274: 178.1 | K274: 150.4 | L274: 115.1 | M274: 160 | N274: 140.6 | O274: 162.3 | P274: 157 | Q274: 182.6 | R274: 153.1 | S274: 143.4 | T274: 151.7 | U274: 155.5 | V274: 143 | W274: 148.4 | X274: 155 | Y274: 138.5 | Z274: 146 | AA274: 158.5 | AB274: 154.3 | AC274: 149 | AD274: 153.9
A275: Rural | B275: 2020 | C275: September | D275: 146.9 | E275: 183.9 | F275: 149.5 | G275: 153.4 | H275: 140.4 | I275: 147 | J275: 178.8 | K275: 149.3 | L275: 115.1 | M275: 160 | N275: 145.4 | O275: 161.6 | P275: 156.1 | Q275: 182.9 | R275: 155.4 | S275: 149.9 | T275: 154.6 | U275: NA | V275: 146.4 | W275: 151.6 | X275: 159.1 | Y275: 144.6 | Z275: 152.8 | AA275: 161.1 | AB275: 157.4 | AC275: 153.7 | AD275: 155.4
A276: Urban | B276: 2020 | C276: September | D276: 151.5 | E276: 193.1 | F276: 157.3 | G276: 153.9 | H276: 134.4 | I276: 155.4 | J276: 202 | K276: 150.8 | L276: 118.9 | M276: 160.9 | N276: 137.7 | O276: 164.4 | P276: 161.3 | Q276: 188.7 | R276: 150.2 | S276: 136.3 | T276: 148.1 | U276: 156.3 | V276: 137.2 | W276: 145.4 | X276: 150 | Y276: 135.1 | Z276: 141.8 | AA276: 154.9 | AB276: 159.8 | AC276: 146 | AD276: 154
A277: Rural+Urban | B277: 2020 | C277: September | D277: 148.4 | E277: 187.1 | F277: 152.5 | G277: 153.6 | H277: 138.2 | I277: 150.9 | J277: 186.7 | K277: 149.8 | L277: 116.4 | M277: 160.3 | N277: 142.2 | O277: 162.9 | P277: 158 | Q277: 184.4 | R277: 153.4 | S277: 144.3 | T277: 152 | U277: 156.3 | V277: 142.9 | W277: 148.7 | X277: 155.6 | Y277: 139.6 | Z277: 146.6 | AA277: 157.5 | AB277: 158.4 | AC277: 150 | AD277: 154.7
... A373: Rural+Urban | B373: 2023 | C373: May | D373: 173.7 | E373: 214.3 | F373: 173.2 | G373: 179.5 | H373: 170 | I373: 172.2 | J373: 161 | K373: 175.6 | L373: 122.7 | M373: 218 | N373: 173.4 | O373: 194.2 | P373: 179.1 | Q373: 201 | R373: 187.3 | S373: 179.7 | T373: 186.2 | U373: 175.6 | V373: 182.8 | W373: 175.2 | X373: 185.7 | Y373: 164.8 | Z373: 171.2 | AA373: 177.1 | AB373: 185.2 | AC373: 175.7 | AD373: 179.1

Sheet category
A1: sub category | B1: category
A2: Cereals and products | B2: food
A3: Meat and fish | B3: food
A4: Egg | B4: food
A5: Milk and products | B5: food
A6: Oils and fats | B6: food
A7: Fruits | B7: food
A8: Vegetables | B8: food
A9: Pulses and products | B9: food
A10: Sugar and Confectionery | B10: food
A11: Spices | B11: food
A12: Non-alcoholic beverages | B12: food
... A24: Personal care and effects | B24: personal care

Sheet 1.category-subcategory
A1: sub category | B1: rural | C1: urban | D1: rural + urban | E1: category
A2: Cereals and products | B2: 173.2 | C2: 174.7 | D2: 173.7 | E2: =VLOOKUP(A2,category!$A$2:$B$24,2,0) -> food
A3: Meat and fish | B3: 211.5 | C3: 219.4 | D3: 214.3 | E3: =VLOOKUP(A3,category!$A$2:$B$24,2,0) -> food
A4: Egg | B4: 171 | C4: 176.7 | D4: 173.2 | E4: =VLOOKUP(A4,category!$A$2:$B$24,2,0) -> food
A5: Milk and products | B5: 179.6 | C5: 179.4 | D5: 179.5 | E5: =VLOOKUP(A5,category!$A$2:$B$24,2,0) -> food
A6: Oils and fats | B6: 173.3 | C6: 164.4 | D6: 170 | E6: =VLOOKUP(A6,category!$A$2:$B$24,2,0) -> food
A7: Fruits | B7: 169 | C7: 175.8 | D7: 172.2 | E7: =VLOOKUP(A7,category!$A$2:$B$24,2,0) -> food
A8: Vegetables | B8: 148.7 | C8: 185 | D8: 161 | E8: =VLOOKUP(A8,category!$A$2:$B$24,2,0) -> food
A9: Pulses and products | B9: 174.9 | C9: 176.9 | D9: 175.6 | E9: =VLOOKUP(A9,category!$A$2:$B$24,2,0) -> food
A10: Sugar and Confectionery | B10: 121.9 | C10: 124.2 | D10: 122.7 | E10: =VLOOKUP(A10,category!$A$2:$B$24,2,0) -> food
A11: Spices | B11: 221 | C11: 211.9 | D11: 218 | E11: =VLOOKUP(A11,category!$A$2:$B$24,2,0) -> food
A12: Non-alcoholic beverages | B12: 178.7 | C12: 165.9 | D12: 173.4 | E12: =VLOOKUP(A12,category!$A$2:$B$24,2,0) -> food
A13: Prepared meals, snacks, sweets etc. | B13: 191.1 | C13: 197.7 | D13: 194.2 | E13: =VLOOKUP(A13,category!$A$2:$B$24,2,0) -> food
... A16: Footwear | B16: 187.9 | C16: 168.1 | D16: 179.7 | E16: =VLOOKUP(A16,category!$A$2:$B$24,2,0) -> clothing
A17: Housing | B17: - | C17: 175.6 | D17: 175.6 | E17: =VLOOKUP(A17,category!$A$2:$B$24,2,0) -> housing
A18: Fuel and light | B18: 182.5 | C18: 183.4 | D18: 182.8 | E18: =VLOOKUP(A18,category!$A$2:$B$24,2,0) -> energy
A19: Household goods and services | B19: 179.8 | C19: 170.1 | D19: 175.2 | E19: =VLOOKUP(A19,category!$A$2:$B$24,2,0) -> household
A20: Health | B20: 187.8 | C20: 182.2 | D20: 185.7 | E20: =VLOOKUP(A20,category!$A$2:$B$24,2,0) -> healthcare
A21: Transport and communication | B21: 169.7 | C21: 160.4 | D21: 164.8 | E21: =VLOOKUP(A21,category!$A$2:$B$24,2,0) -> transport
A22: Recreation and amusement | B22: 173.8 | C22: 169.2 | D22: 171.2 | E22: =VLOOKUP(A22,category!$A$2:$B$24,2,0) -> recreation
A23: Education | B23: 180.3 | C23: 174.8 | D23: 177.1 | E23: =VLOOKUP(A23,category!$A$2:$B$24,2,0) -> education
A24: Personal care and effects | B24: 184.9 | C24: 185.6 | D24: 185.2 | E24: =VLOOKUP(A24,category!$A$2:$B$24,2,0) -> personal care

Sheet Ques 1
A1: Sub Category | B1: Broader Category
A2: Cereals and products | B2: food | E2: The contribution of different categories to the overall CPI
A3: Meat and fish | B3: food | K3: Key Insight
A4: Egg | B4: food | K4: Food contributes 51.73% of the overall CPI basket.
A5: Milk and products | B5: food | E5: Based on the latest month data | K5: It is the largest contributor among all broader categories.
A6: Oils and fats | B6: food
A7: Fruits | B7: food
A8: Vegetables | B8: food | D8: Broader Category | E8: Contribution (%)
A9: Pulses and products | B9: food | D9: clothing | E9: 0.089220596
A10: Sugar and Confectionery | B10: food | D10: education | E10: 0.043054408
A11: Spices | B11: food | D11: energy | E11: 0.044440123
A12: Non-alcoholic beverages | B12: food | D12: food | E12: 0.51728497
A13: Prepared meals, snacks, sweets etc. | B13: food | D13: healthcare | E13: 0.045145135
A14: Pan, tobacco and intoxicants | B14: tabacco & intoxicants | D14: household | E14: 0.042592503
A15: Clothing | B15: clothing | D15: housing | E15: 0.042689746
A16: Footwear | B16: clothing | D16: personal care | E16: 0.045023581
A17: Housing | B17: housing | D17: recreation | E17: 0.041620071
A18: Fuel and light | B18: energy | D18: tabacco & intoxicants | E18: 0.048864686
A19: Household goods and services | B19: household | D19: transport | E19: 0.04006418
A20: Health | B20: healthcare | D20: Grand Total | E20: 1
A21: Transport and communication | B21: transport
A22: Recreation and amusement | B22: recreation
A23: Education | B23: education
A24: Personal care and effects | B24: personal care

Sheet CPI (2)
A1: Year | B1: Sector | C1: General index
A2: 2017 | B2: Rural+Urban | C2: 130.3
A3: 2017 | B3: Rural+Urban | C3: 130.6
A4: 2017 | B4: Rural+Urban | C4: 130.9
A5: 2017 | B5: Rural+Urban | C5: 131.1
A6: 2017 | B6: Rural+Urban | C6: 131.4
A7: 2017 | B7: Rural+Urban | C7: 132
A8: 2017 | B8: Rural+Urban | C8: 134.2
A9: 2017 | B9: Rural+Urban | C9: 135.4
A10: 2017 | B10: Rural+Urban | C10: 135.2
A11: 2017 | B11: Rural+Urban | C11: 136.1
A12: 2017 | B12: Rural+Urban | C12: 137.6
A13: 2017 | B13: Rural+Urban | C13: 137.2
... A39: 2020 | B39: Rural+Urban | C39: 148.6
A40: 2020 | B40: Rural+Urban
A41: 2020 | B41: Rural+Urban
A42: 2020 | B42: Rural+Urban | C42: 151.8
A43: 2020 | B43: Rural+Urban | C43: 151.8
A44: 2020 | B44: Rural+Urban | C44: 153.9
A45: 2020 | B45: Rural+Urban | C45: 154.7
A46: 2020 | B46: Rural+Urban | C46: 156.4
A47: 2020 | B47: Rural+Urban | C47: 158.4
A48: 2020 | B48: Rural+Urban | C48: 158.9
A49: 2021 | B49: Rural+Urban | C49: 157.3
A50: 2021 | B50: Rural+Urban | C50: 156.6
A51: 2021 | B51: Rural+Urban | C51: 156.8
A52: 2021 | B52: Rural+Urban | C52: 157.8
A53: 2021 | B53: Rural+Urban | C53: 160.4
... A77: 2023 | B77: Rural+Urban | C77: 179.1

Sheet Ques 2
F2: Year-over-Year (YoY) Inflation Trend (2017–2023)
A3: Year | B3: Average CPI Index
A4: 2017 | B4: 133.5
A5: 2018 | B5: 138.775
A6: 2019 | B6: 144.18182 | L6: Key Outputs
A7: 2020 | B7: 153.38
A8: 2021 | B8: 161.45833 | L8: Highest average inflation occurred in 2022 (6.62%).
A9: 2022 | B9: 172.15 | L9: In 2022, oil prices went up and the Russia-Ukraine war disturbed supplies. COVID effects were also still there. All this together pushed prices up a lot.
A10: 2023 | B10: 177.62
A11: Grand Total | B11: 152.41216
L13: Inflation peaked during 2020–2022, indicating a period of higher price increases.
A14: Year | B14: YOY % | L14: COVID disturbed supply of goods from 2020. When demand came back fast, supply couldn't match it. This gap kept prices high for 3 years.
A15: {=A4:A10} -> 2017
A16: 2018 | B16: =(B5-B4)/B4 -> 0.039513109
A17: 2019 | B17: =(B6-B5)/B5 -> 0.038961039
A18: 2020 | B18: =(B7-B6)/B6 -> 0.063795712 | L18: Inflation declined to 3.18% in 2023, suggesting easing inflationary pressure.
A19: 2021 | B19: =(B8-B7)/B7 -> 0.052668753 | L19: By 2023, supply improved and oil prices became stable. The war's effect also reduced. So prices didn't rise as fast, and inflation dropped to 3.18%.
A20: 2022 | B20: =(B9-B8)/B8 -> 0.066219355
A21: 2023 | B21: =(B10-B9)/B9 -> 0.031774615

Sheet Ques3 A
C2: Month-over-Month (MoM) Food Inflation Analysis (June 2022 – May 2023)
B4: Month | C4: Food CPI Index | D4: MoM Inflation (%)
B5: 2022-June | C5: 174.9
B6: 2022-July | C6: 175 | D6: =(C6-C5)/C5 -> 0.00057175529
B7: 2022-August | C7: 176.3 | D7: =(C7-C6)/C6 -> 0.0074285714
B8: 2022-September | C8: 177.8 | D8: =(C8-C7)/C7 -> 0.0085082246
B9: 2022-October | C9: 179.6 | D9: =(C9-C8)/C8 -> 0.010123735
B10: 2022-November | C10: 178.3 | D10: =(C10-C9)/C9 -> -0.0072383073
B11: 2022-December | C11: 175.9 | D11: =(C11-C10)/C10 -> -0.01346046
B12: 2023-January | C12: 176.7 | D12: =(C12-C11)/C11 -> 0.0045480387
B13: 2023-February | C13: 177 | D13: =(C13-C12)/C12 -> 0.0016977929
B14: 2023-March | C14: 177 | D14: =(C14-C13)/C13 -> 0
B15: 2023-April | C15: 177.9 | D15: =(C15-C14)/C14 -> 0.0050847458
B16: 2023-May | C16: 179.1 | D16: =(C16-C15)/C15 -> 0.0067453626
B19: Key Insight
B21: Highest monthly food inflation occurred in October 2022 (1.01%).
B22: In October, the new crop of vegetables hasn't fully arrived in the market yet, so supply is low. On top of that, the monsoon withdrew unevenly in 2022, which damaged crops and disrupted transport — making supply even tighter. At the same time, festival season (Diwali) increased demand for food. Less supply + more demand = higher prices.
B29: Lowest monthly food inflation occurred in December 2022 (-1.35%).
B30: By December, fresh winter vegetables (like tomatoes and onions) arrive in large quantities. More supply means prices drop. Cooler weather also helps vegetables stay fresh longer, so there's less wastage and even more supply in the market — pushing prices down further.

Sheet Ques3 B
B2: Absolute Change in Food Category CPI Index (June 2022 – May 2023)
B5: Food Subcategory | C5: June 2022 CPI | D5: May 2023 CPI | E5: Absolute Change
B6: Cereals and products | C6: 155 | D6: 173.7 | E6: =D6-C6 -> 18.7
B7: Meat and fish | C7: 219.4 | D7: 214.3 | E7: =D7-C7 -> -5.1
B8: Egg | C8: 170.8 | D8: 173.2 | E8: =D8-C8 -> 2.4
B9: Milk and products | C9: 165.8 | D9: 179.5 | E9: =D9-C9 -> 13.7
B10: Oils and fats | C10: 200.9 | D10: 170 | E10: =D10-C10 -> -30.9
B11: Fruits | C11: 169.7 | D11: 172.2 | E11: =D11-C11 -> 2.5
B12: Vegetables | C12: 182.3 | D12: 161 | E12: =D12-C12 -> -21.3
B13: Pulses and products | C13: 164.3 | D13: 175.6 | E13: =D13-C13 -> 11.3
B14: Sugar and Confectionery | C14: 119.9 | D14: 122.7 | E14: =D14-C14 -> 2.8
B15: Spices | C15: 187.1 | D15: 218 | E15: =D15-C15 -> 30.9
B16: Non-alcoholic beverages | C16: 167.9 | D16: 173.4 | E16: =D16-C16 -> 5.5
B17: Prepared meals, snacks, sweets etc. | C17: 183.9 | D17: 194.2 | E17: =D17-C17 -> 10.3
B20: Key Insights
B21: Spices recorded the highest increase in the CPI Index, rising by 30.9 points between June 2022 and May 2023.
B23: Spices like jeera, chilli, and turmeric had lower crop output due to bad weather in growing regions. Less supply with steady demand pushed their prices up a lot.
B27: Oils & Fats (-30.9) and Vegetables (-21.3) showed the largest declines over the same period.
B29: Global edible oil prices (palm oil, sunflower oil) fell sharply in this period after export bans were lifted and supply improved worldwide. This made oils cheaper in India too.
B32: After the high vegetable prices in late 2022, fresh harvests arrived in bulk in winter/spring, increasing supply. More supply meant lower prices, so vegetables became cheaper by May 2023.

Sheet Ques 4
A1: Date | B1: Food and beverages | C1: Fuel and light | D1: Household goods and services | E1: Health | F1: Transport and communication | G1: General index | H1: Food and Beverages MoM % | I1: Fuel and Light MoM% | J1: Household goods and services MoM% | K1: Health MoM% | L1: Transport and Communication MoM% | M1: General index Mom%
A2: 2017-March | B2: 133.1 | C2: 129.1 | D2: 130.1 | E2: 127.8 | F2: 117.6 | G2: 130.9 | P2: Impact of COVID-19 on CPI Inflation (Pre-COVID vs Post-COVID)
A3: 2017-April | B3: 133.5 | C3: 129.8 | D3: 130.4 | E3: 128.1 | F3: 116.6 | G3: 131.1 | H3: =(B3-B2)/B2 -> 0.0030052592 | I3: =(C3-C2)/C2 -> 0.0054221534 | J3: =(D3-D2)/D2 -> 0.0023059185 | K3: =(E3-E2)/E2 -> 0.0023474178 | L3: =(F3-F2)/F2 -> -0.0085034014 | M3: =(G3-G2)/G2 -> 0.0015278839
A4: 2017-May | B4: 133.7 | C4: 129.4 | D4: 130.9 | E4: 128.4 | F4: 116.7 | G4: 131.4 | H4: =(B4-B3)/B3 -> 0.0014981273 | I4: =(C4-C3)/C3 -> -0.0030816641 | J4: =(D4-D3)/D3 -> 0.0038343558 | K4: =(E4-E3)/E3 -> 0.0023419204 | L4: =(F4-F3)/F3 -> 0.00085763293 | M4: =(G4-G3)/G3 -> 0.0022883295
A5: 2017-June | B5: 135.2 | C5: 128.8 | D5: 131.2 | E5: 128.5 | F5: 116.5 | G5: 132 | H5: =(B5-B4)/B4 -> 0.011219147 | I5: =(C5-C4)/C4 -> -0.0046367852 | J5: =(D5-D4)/D4 -> 0.0022918258 | K5: =(E5-E4)/E4 -> 0.0007788162 | L5: =(F5-F4)/F4 -> -0.0017137961 | M5: =(G5-G4)/G4 -> 0.00456621
A6: 2017-July | B6: 139 | C6: 129.4 | D6: 131.9 | E6: 129.4 | F6: 116 | G6: 134.2 | H6: =(B6-B5)/B5 -> 0.028106509 | I6: =(C6-C5)/C5 -> 0.0046583851 | J6: =(D6-D5)/D5 -> 0.0053353659 | K6: =(E6-E5)/E5 -> 0.0070038911 | L6: =(F6-F5)/F5 -> -0.0042918455 | M6: =(G6-G5)/G5 -> 0.016666667
A7: 2017-August | B7: 140.6 | C7: 129.8 | D7: 132.8 | E7: 130.2 | F7: 117.3 | G7: 135.4 | H7: =(B7-B6)/B6 -> 0.011510791 | I7: =(C7-C6)/C6 -> 0.0030911901 | J7: =(D7-D6)/D6 -> 0.006823351 | K7: =(E7-E6)/E6 -> 0.0061823802 | L7: =(F7-F6)/F6 -> 0.011206897 | M7: =(G7-G6)/G6 -> 0.0089418778 | P7: Pre-Covid | Q7: Post-Covid | R7: Difference (%)
A8: 2017-September | B8: 139 | C8: 131 | D8: 133.3 | E8: 130.6 | F8: 118.3 | G8: 135.2 | H8: =(B8-B7)/B7 -> -0.011379801 | I8: =(C8-C7)/C7 -> 0.0092449923 | J8: =(D8-D7)/D7 -> 0.0037650602 | K8: =(E8-E7)/E7 -> 0.0030721966 | L8: =(F8-F7)/F7 -> 0.0085251492 | M8: =(G8-G7)/G7 -> -0.0014771049 | O8: General CPI | P8: =AVERAGE(M2:M37) -> 0.0036454824 | Q8: =AVERAGE(M38:M73) -> 0.0050708618 | R8: =Q8-P8 -> 0.0014253794
A9: 2017-October | B9: 140.1 | C9: 132.2 | D9: 133.6 | E9: 131.3 | F9: 117.8 | G9: 136.1 | H9: =(B9-B8)/B8 -> 0.0079136691 | I9: =(C9-C8)/C8 -> 0.0091603053 | J9: =(D9-D8)/D8 -> 0.0022505626 | K9: =(E9-E8)/E8 -> 0.0053598775 | L9: =(F9-F8)/F8 -> -0.0042265427 | M9: =(G9-G8)/G8 -> 0.0066568047 | O9: Fuel and Light | P9: =AVERAGE(I2:I37) -> 0.0041310196 | Q9: =AVERAGE(I38:I73) -> 0.0057006995 | R9: =Q9-P9 -> 0.0015696799
A10: 2017-November | B10: 142.1 | C10: 135.3 | D10: 134.4 | E10: 132.6 | F10: 118.3 | G10: 137.6 | H10: =(B10-B9)/B9 -> 0.014275517 | I10: =(C10-C9)/C9 -> 0.023449319 | J10: =(D10-D9)/D9 -> 0.005988024 | K10: =(E10-E9)/E9 -> 0.0099009901 | L10: =(F10-F9)/F9 -> 0.0042444822 | M10: =(G10-G9)/G9 -> 0.011021308 | O10: Food and Beverages | P10: =AVERAGE(H2:H37) -> 0.0032739578 | Q10: =AVERAGE(H38:H73) -> 0.0049459848 | R10: =Q10-P10 -> 0.0016720271
A11: 2017-December | B11: 140.5 | C11: 136.6 | D11: 134.7 | E11: 133.1 | F11: 118.5 | G11: 137.2 | H11: =(B11-B10)/B10 -> -0.011259676 | I11: =(C11-C10)/C10 -> 0.0096082779 | J11: =(D11-D10)/D10 -> 0.0022321429 | K11: =(E11-E10)/E10 -> 0.0037707391 | L11: =(F11-F10)/F10 -> 0.0016906171 | M11: =(G11-G10)/G10 -> -0.0029069767 | O11: Household goods and Services | P11: =AVERAGE(J2:J37) -> 0.0033834311 | Q11: =AVERAGE(J38:J73) -> 0.0049801831 | R11: =Q11-P11 -> 0.001596752
A12: 2018-January | B12: 139.2 | C12: 136.6 | D12: 134.9 | E12: 133.3 | F12: 119.3 | G12: 136.9 | H12: =(B12-B11)/B11 -> -0.009252669 | I12: =(C12-C11)/C11 -> 0 | J12: =(D12-D11)/D11 -> 0.001484781 | K12: =(E12-E11)/E11 -> 0.0015026296 | L12: =(F12-F11)/F11 -> 0.0067510549 | M12: =(G12-G11)/G11 -> -0.0021865889 | O12: Transport and Communication | P12: =AVERAGE(L2:L37) -> 0.0028705921 | Q12: =AVERAGE(L38:L73) -> 0.0066132113 | R12: =Q12-P12 -> 0.0037426192
A13: 2018-February | B13: 137.6 | C13: 136.7 | D13: 135.2 | E13: 133.8 | F13: 120.2 | G13: 136.4 | H13: =(B13-B12)/B12 -> -0.011494253 | I13: =(C13-C12)/C12 -> 0.00073206442 | J13: =(D13-D12)/D12 -> 0.0022238695 | K13: =(E13-E12)/E12 -> 0.0037509377 | L13: =(F13-F12)/F12 -> 0.0075440067 | M13: =(G13-G12)/G12 -> -0.0036523009 | O13: Health | P13: =AVERAGE(K2:K37) -> 0.0050355939 | Q13: =AVERAGE(K38:K73) -> 0.0056002594 | R13: =Q13-P13 -> 0.00056466549
A14: 2018-March | B14: 137.2 | C14: 136.5 | D14: 135.6 | E14: 134.3 | F14: 121 | G14: 136.5 | H14: =(B14-B13)/B13 -> -0.0029069767 | I14: =(C14-C13)/C13 -> -0.0014630578 | J14: =(D14-D13)/D13 -> 0.0029585799 | K14: =(E14-E13)/E13 -> 0.0037369208 | L14: =(F14-F13)/F13 -> 0.006655574 | M14: =(G14-G13)/G13 -> 0.00073313783
A15: 2018-April | B15: 137.5 | C15: 136.5 | D15: 136.6 | E15: 135.2 | F15: 121.9 | G15: 137.1 | H15: =(B15-B14)/B14 -> 0.0021865889 | I15: =(C15-C14)/C14 -> 0 | J15: =(D15-D14)/D14 -> 0.0073746313 | K15: =(E15-E14)/E14 -> 0.0067014147 | L15: =(F15-F14)/F14 -> 0.0074380165 | M15: =(G15-G14)/G14 -> 0.0043956044
A16: 2018-May | B16: 138.1 | C16: 136.9 | D16: 137.4 | E16: 136 | F16: 122.9 | G16: 137.8 | H16: =(B16-B15)/B15 -> 0.0043636364 | I16: =(C16-C15)/C15 -> 0.0029304029 | J16: =(D16-D15)/D15 -> 0.0058565154 | K16: =(E16-E15)/E15 -> 0.0059171598 | L16: =(F16-F15)/F15 -> 0.0082034454 | M16: =(G16-G15)/G15 -> 0.0051057622
A17: 2018-June | B17: 139.4 | C17: 138.1 | D17: 137.9 | E17: 136.2 | F17: 123.7 | G17: 138.5 | H17: =(B17-B16)/B16 -> 0.0094134685 | I17: =(C17-C16)/C16 -> 0.0087655223 | J17: =(D17-D16)/D16 -> 0.0036390102 | K17: =(E17-E16)/E16 -> 0.0014705882 | L17: =(F17-F16)/F16 -> 0.0065093572 | M17: =(G17-G16)/G16 -> 0.0050798258 | O17: Key Insights
A18: 2018-July | B18: 141.4 | C18: 139.7 | D18: 138.6 | E18: 137 | F18: 123.6 | G18: 139.8 | H18: =(B18-B17)/B17 -> 0.014347202 | I18: =(C18-C17)/C17 -> 0.011585807 | J18: =(D18-D17)/D17 -> 0.0050761421 | K18: =(E18-E17)/E17 -> 0.0058737151 | L18: =(F18-F17)/F17 -> -0.00080840744 | M18: =(G18-G17)/G17 -> 0.0093862816 | O18: Transport & Communication showed the highest increase after COVID (+0.37%).
A19: 2018-August | B19: 141.7 | C19: 140.9 | D19: 139.4 | E19: 137.7 | F19: 124.3 | G19: 140.4 | H19: =(B19-B18)/B18 -> 0.0021216407 | I19: =(C19-C18)/C18 -> 0.0085898354 | J19: =(D19-D18)/D18 -> 0.0057720058 | K19: =(E19-E18)/E18 -> 0.0051094891 | L19: =(F19-F18)/F18 -> 0.0056634304 | M19: =(G19-G18)/G18 -> 0.0042918455
A20: 2018-September | B20: 140.4 | C20: 142.3 | D20: 139.7 | E20: 138.4 | F20: 126 | G20: 140.2 | H20: =(B20-B19)/B19 -> -0.0091743119 | I20: =(C20-C19)/C19 -> 0.0099361249 | J20: =(D20-D19)/D19 -> 0.0021520803 | K20: =(E20-E19)/E19 -> 0.0050835149 | L20: =(F20-F19)/F19 -> 0.013676589 | M20: =(G20-G19)/G19 -> -0.0014245014 | O20: After COVID, crude oil prices went up a lot, making petrol and diesel costlier.
A21: 2018-October | B21: 139.7 | C21: 145.3 | D21: 142.2 | E21: 142.1 | F21: 125.5 | G21: 140.8 | H21: =(B21-B20)/B20 -> -0.004985755 | I21: =(C21-C20)/C20 -> 0.021082221 | J21: =(D21-D20)/D20 -> 0.01789549 | K21: =(E21-E20)/E20 -> 0.026734104 | L21: =(F21-F20)/F20 -> -0.003968254 | M21: =(G21-G20)/G20 -> 0.0042796006
A22: 2018-November | B22: 139.7 | C22: 145.1 | D22: 142.2 | E22: 142.1 | F22: 125.5 | G22: 140.8 | H22: =(B22-B21)/B21 -> 0 | I22: =(C22-C21)/C21 -> -0.0013764625 | J22: =(D22-D21)/D21 -> 0 | K22: =(E22-E21)/E21 -> 0 | L22: =(F22-F21)/F21 -> 0 | M22: =(G22-G21)/G21 -> 0 | O22: Food & Beverages and Fuel & Light also experienced noticeable increases.
A23: 2018-December | B23: 138.2 | C23: 142.7 | D23: 143.2 | E23: 144.9 | F23: 123.6 | G23: 140.1 | H23: =(B23-B22)/B22 -> -0.010737294 | I23: =(C23-C22)/C22 -> -0.016540317 | J23: =(D23-D22)/D22 -> 0.0070323488 | K23: =(E23-E22)/E22 -> 0.019704433 | L23: =(F23-F22)/F22 -> -0.015139442 | M23: =(G23-G22)/G22 -> -0.0049715909
A24: 2019-January | B24: 137.4 | C24: 139.5 | D24: 143.6 | E24: 145.1 | F24: 123.3 | G24: 139.6 | H24: =(B24-B23)/B23 -> -0.005788712 | I24: =(C24-C23)/C23 -> -0.022424667 | J24: =(D24-D23)/D23 -> 0.0027932961 | K24: =(E24-E23)/E23 -> 0.0013802622 | L24: =(F24-F23)/F23 -> -0.0024271845 | M24: =(G24-G23)/G23 -> -0.0035688794 | O24: Supply chains were disturbed during COVID, and demand rose faster than supply once things reopened. Higher fuel costs also made transporting food more expensive, pushing up both categories.
A25: 2019-February | B25: 137.5 | C25: 138.4 | D25: 143.7 | E25: 145.6 | F25: 123.9 | G25: 139.9 | H25: =(B25-B24)/B24 -> 0.00072780204 | I25: =(C25-C24)/C24 -> -0.0078853047 | J25: =(D25-D24)/D24 -> 0.00069637883 | K25: =(E25-E24)/E24 -> 0.0034458994 | L25: =(F25-F24)/F24 -> 0.00486618 | M25: =(G25-G24)/G24 -> 0.0021489971
A26: 2019-March | B26: 138.1 | C26: 139.7 | D26: 143.8 | E26: 146.2 | F26: 124.6 | G26: 140.4 | H26: =(B26-B25)/B25 -> 0.0043636364 | I26: =(C26-C25)/C25 -> 0.0093930636 | J26: =(D26-D25)/D25 -> 0.00069589422 | K26: =(E26-E25)/E25 -> 0.0041208791 | L26: =(F26-F25)/F25 -> 0.0056497175 | M26: =(G26-G25)/G25 -> 0.0035739814
A27: 2019-May | B27: 140.9 | C27: 140.3 | D27: 143.7 | E27: 146.9 | F27: 124.9 | G27: 142 | H27: =(B27-B26)/B26 -> 0.020275163 | I27: =(C27-C26)/C26 -> 0.0042949177 | J27: =(D27-D26)/D26 -> -0.00069541029 | K27: =(E27-E26)/E26 -> 0.0047879617 | L27: =(F27-F26)/F26 -> 0.0024077047 | M27: =(G27-G26)/G26 -> 0.011396011
A28: 2019-June | B28: 142.7 | C28: 141.2 | D28: 143.8 | E28: 147.4 | F28: 124.6 | G28: 142.9 | H28: =(B28-B27)/B27 -> 0.012775018 | I28: =(C28-C27)/C27 -> 0.0064148254 | J28: =(D28-D27)/D27 -> 0.00069589422 | K28: =(E28-E27)/E27 -> 0.003403676 | L28: =(F28-F27)/F27 -> -0.0024019215 | M28: =(G28-G27)/G27 -> 0.0063380282 | O28: General CPI increased after COVID, indicating overall inflationary pressure.
A29: 2019-July | B29: 144.7 | C29: 139.3 | D29: 144.2 | E29: 147.9 | F29: 125.6 | G29: 144.2 | H29: =(B29-B28)/B28 -> 0.014015417 | I29: =(C29-C28)/C28 -> -0.013456091 | J29: =(D29-D28)/D28 -> 0.0027816412 | K29: =(E29-E28)/E28 -> 0.0033921303 | L29: =(F29-F28)/F28 -> 0.0080256822 | M29: =(G29-G28)/G28 -> 0.0090972708
A30: 2019-August | B30: 145.9 | C30: 138.5 | D30: 144.5 | E30: 148.5 | F30: 125.8 | G30: 145 | H30: =(B30-B29)/B29 -> 0.00829302 | I30: =(C30-C29)/C29 -> -0.0057430007 | J30: =(D30-D29)/D29 -> 0.0020804438 | K30: =(E30-E29)/E29 -> 0.0040567951 | L30: =(F30-F29)/F29 -> 0.0015923567 | M30: =(G30-G29)/G29 -> 0.0055478502 | O30: Since most categories (transport, food, fuel) became costlier at the same time, the overall CPI also went up, showing that inflation was rising across the whole economy, not just one sector.
A31: 2019-September | B31: 147 | C31: 139.2 | D31: 144.6 | E31: 149 | F31: 126.1 | G31: 145.8 | H31: =(B31-B30)/B30 -> 0.0075394106 | I31: =(C31-C30)/C30 -> 0.0050541516 | J31: =(D31-D30)/D30 -> 0.00069204152 | K31: =(E31-E30)/E30 -> 0.0033670034 | L31: =(F31-F30)/F30 -> 0.0023847377 | M31: =(G31-G30)/G30 -> 0.0055172414
A32: 2019-October | B32: 149.6 | C32: 140.6 | D32: 145 | E32: 149.4 | F32: 126.3 | G32: 147.2 | H32: =(B32-B31)/B31 -> 0.017687075 | I32: =(C32-C31)/C31 -> 0.010057471 | J32: =(D32-D31)/D31 -> 0.0027662517 | K32: =(E32-E31)/E31 -> 0.0026845638 | L32: =(F32-F31)/F31 -> 0.0015860428 | M32: =(G32-G31)/G31 -> 0.0096021948
A33: 2019-November | B33: 151.9 | C33: 142.3 | D33: 145.3 | E33: 149.9 | F33: 126.6 | G33: 148.6 | H33: =(B33-B32)/B32 -> 0.015374332 | I33: =(C33-C32)/C32 -> 0.012091038 | J33: =(D33-D32)/D32 -> 0.0020689655 | K33: =(E33-E32)/E32 -> 0.0033467202 | L33: =(F33-F32)/F32 -> 0.0023752969 | M33: =(G33-G32)/G32 -> 0.0095108696
A34: 2019-December | B34: 155 | C34: 143.7 | D34: 145.8 | E34: 150.4 | F34: 129.8 | G34: 150.4 | H34: =(B34-B33)/B33 -> 0.020408163 | I34: =(C34-C33)/C33 -> 0.0098383696 | J34: =(D34-D33)/D33 -> 0.0034411562 | K34: =(E34-E33)/E33 -> 0.003335557 | L34: =(F34-F33)/F33 -> 0.025276461 | M34: =(G34-G33)/G33 -> 0.012113055
A35: 2020-January | B35: 153.5 | C35: 144.6 | D35: 146.2 | E35: 151.2 | F35: 130.9 | G35: 150.2 | H35: =(B35-B34)/B34 -> -0.0096774194 | I35: =(C35-C34)/C34 -> 0.006263048 | J35: =(D35-D34)/D34 -> 0.0027434842 | K35: =(E35-E34)/E34 -> 0.0053191489 | L35: =(F35-F34)/F34 -> 0.0084745763 | M35: =(G35-G34)/G34 -> -0.0013297872
A36: 2020-February | B36: 150.5 | C36: 147.2 | D36: 146.4 | E36: 151.7 | F36: 130.3 | G36: 149.1 | H36: =(B36-B35)/B35 -> -0.019543974 | I36: =(C36-C35)/C35 -> 0.017980636 | J36: =(D36-D35)/D35 -> 0.0013679891 | K36: =(E36-E35)/E35 -> 0.0033068783 | L36: =(F36-F35)/F35 -> -0.0045836516 | M36: =(G36-G35)/G35 -> -0.0073235686
A37: 2020-March | B37: 148.9 | C37: 148.9 | D37: 146.4 | E37: 152.3 | F37: 129.9 | G37: 148.6 | H37: =(B37-B36)/B36 -> -0.010631229 | I37: =(C37-C36)/C36 -> 0.011548913 | J37: =(D37-D36)/D36 -> 0 | K37: =(E37-E36)/E36 -> 0.0039551747 | L37: =(F37-F36)/F36 -> -0.0030698388 | M37: =(G37-G36)/G36 -> -0.0033534541
A38: 2020-April | B38: 151.4 | C38: 144.1 | D38: 136.68 | E38: 150.7 | F38: 127.17 | G38: 139.56 | H38: =(B38-B37)/B37 -> 0.016789792 | I38: =(C38-C37)/C37 -> -0.0322364 | J38: =(D38-D37)/D37 -> -0.066393443 | K38: =(E38-E37)/E37 -> -0.010505581 | L38: =(F38-F37)/F37 -> -0.021016166 | M38: =(G38-G37)/G37 -> -0.060834455
A39: 2020-May | B39: 145.51 | C39: 136.51 | D39: 136.68 | E39: 138.51 | F39: 127.17 | G39: 139.56 | H39: =(B39-B38)/B38 -> -0.038903567 | I39: =(C39-C38)/C38 -> -0.052671756 | J39: =(D39-D38)/D38 -> 0 | K39: =(E39-E38)/E38 -> -0.080889184 | L39: =(F39-F38)/F38 -> 0 | M39: =(G39-G38)/G38 -> 0
A40: 2020-June | B40: 154 | C40: 141.9 | D40: 146.4 | E40: 154.4 | F40: 135 | G40: 151.8 | H40: =(B40-B39)/B39 -> 0.058346505 | I40: =(C40-C39)/C39 -> 0.039484287 | J40: =(D40-D39)/D39 -> 0.071115013 | K40: =(E40-E39)/E39 -> 0.11472096 | L40: =(F40-F39)/F39 -> 0.061571125 | M40: =(G40-G39)/G39 -> 0.087704213
...

Sheet Ques 5 Category
A1: Date | B1: Food and beverages | C1: Fuel and light | D1: Health | E1: Transport and communication | F1: Recreation and amusement | G1: Education | H1: General index | I1: Crude Oil | J1: Food and Beverages MoM % | K1: Fuel and Light MoM% | L1: Health MoM% | M1: Transport and Communication MoM% | N1: Recreation and amusement MoM% | O1: Education MoM% | P1: Crude Oil MoM % | Q1: General Index MoM%
A2: 2021-January | B2: 161 | C2: 147.9 | D2: 159.3 | E2: 141.9 | F2: 149.6 | G2: 159.2 | H2: 157.3 | I2: 54.77 | T2: Impact of Crude Oil Price Fluctuations on CPI Categories (Correlation Analysis: 2021–2023)
A3: 2021-February | B3: 156.9 | C3: 152.4 | D3: 161.3 | E3: 145.1 | F3: 151.5 | G3: 159.5 | H3: 156.6 | I3: 62.28 | J3: =(B3-B2)/B2 -> -0.025465839 | K3: =(C3-C2)/C2 -> 0.030425963 | L3: =(D3-D2)/D2 -> 0.012554928 | M3: =(E3-E2)/E2 -> 0.022551092 | N3: =(F3-F2)/F2 -> 0.012700535 | O3: =(G3-G2)/G2 -> 0.0018844221 | P3: =(I3-I2)/I2 -> 0.13711886 | Q3: =(H3-H2)/H2 -> -0.0044500954
A4: 2021-March | B4: 156.7 | C4: 155.5 | D4: 161.7 | E4: 146.2 | F4: 152.6 | G4: 160.2 | H4: 156.8 | I4: 65.41 | J4: =(B4-B3)/B3 -> -0.0012746973 | K4: =(C4-C3)/C3 -> 0.020341207 | L4: =(D4-D3)/D3 -> 0.0024798512 | M4: =(E4-E3)/E3 -> 0.0075809786 | N4: =(F4-F3)/F3 -> 0.0072607261 | O4: =(G4-G3)/G3 -> 0.0043887147 | P4: =(I4-I3)/I3 -> 0.050256904 | Q4: =(H4-H3)/H3 -> 0.0012771392
A5: 2021-April | B5: 158 | C5: 155.6 | D5: 162.3 | E5: 146.6 | F5: 153.2 | G5: 160.3 | H5: 157.8 | I5: 64.81 | J5: =(B5-B4)/B4 -> 0.0082961072 | K5: =(C5-C4)/C4 -> 0.00064308682 | L5: =(D5-D4)/D4 -> 0.0037105751 | M5: =(E5-E4)/E4 -> 0.0027359781 | N5: =(F5-F4)/F4 -> 0.003931848 | O5: =(G5-G4)/G4 -> 0.00062421973 | P5: =(I5-I4)/I4 -> -0.0091729093 | Q5: =(H5-H4)/H4 -> 0.006377551
A6: 2021-May | B6: 160.7 | C6: 159.4 | D6: 165.8 | E6: 148.9 | F6: 155.8 | G6: 161.2 | H6: 160.4 | I6: 68.53 | J6: =(B6-B5)/B5 -> 0.017088608 | K6: =(C6-C5)/C5 -> 0.024421594 | L6: =(D6-D5)/D5 -> 0.021565003 | M6: =(E6-E5)/E5 -> 0.01568895 | N6: =(F6-F5)/F5 -> 0.016971279 | O6: =(G6-G5)/G5 -> 0.0056144729 | P6: =(I6-I5)/I5 -> 0.05739855 | Q6: =(H6-H5)/H5 -> 0.016476553
A7: 2021-June | B7: 162.6 | C7: 159.8 | D7: 166.3 | E7: 150.7 | F7: 154.9 | G7: 161.7 | H7: 161.3 | I7: 73.16 | J7: =(B7-B6)/B6 -> 0.011823273 | K7: =(C7-C6)/C6 -> 0.0025094103 | L7: =(D7-D6)/D6 -> 0.0030156815 | M7: =(E7-E6)/E6 -> 0.01208865 | N7: =(F7-F6)/F6 -> -0.0057766367 | O7: =(G7-G6)/G6 -> 0.003101737 | P7: =(I7-I6)/I6 -> 0.067561652 | Q7: =(H7-H6)/H6 -> 0.0056109726
A8: 2021-July | B8: 164 | C8: 160.7 | D8: 167 | E8: 153.1 | F8: 155.3 | G8: 163.2 | H8: 162.5 | I8: 75.17 | J8: =(B8-B7)/B7 -> 0.0086100861 | K8: =(C8-C7)/C7 -> 0.0056320401 | L8: =(D8-D7)/D7 -> 0.0042092604 | M8: =(E8-E7)/E7 -> 0.01592568 | N8: =(F8-F7)/F7 -> 0.0025823112 | O8: =(G8-G7)/G7 -> 0.0092764378 | P8: =(I8-I7)/I7 -> 0.02747403 | Q8: =(H8-H7)/H7 -> 0.0074395536
A9: 2021-August | B9: 164 | C9: 162.6 | D9: 168.4 | E9: 154 | F9: 157.6 | G9: 163.8 | H9: 163.2 | I9: 70.75 | J9: =(B9-B8)/B8 -> 0 | K9: =(C9-C8)/C8 -> 0.011823273 | L9: =(D9-D8)/D8 -> 0.0083832335 | M9: =(E9-E8)/E8 -> 0.0058785108 | N9: =(F9-F8)/F8 -> 0.014810045 | O9: =(G9-G8)/G8 -> 0.0036764706 | P9: =(I9-I8)/I8 -> -0.058800053 | Q9: =(H9-H8)/H8 -> 0.0043076923 | S9: Category | T9: Correlation with Crude Oil MoM % | U9: strength
A10: 2021-September | B10: 164 | C10: 162.6 | D10: 168.4 | E10: 154 | F10: 157.7 | G10: 163.7 | H10: 163.2 | I10: 74.49 | J10: =(B10-B9)/B9 -> 0 | K10: =(C10-C9)/C9 -> 0 | L10: =(D10-D9)/D9 -> 0 | M10: =(E10-E9)/E9 -> 0 | N10: =(F10-F9)/F9 -> 0.00063451777 | O10: =(G10-G9)/G9 -> -0.00061050061 | P10: =(I10-I9)/I9 -> 0.052862191 | Q10: =(H10-H9)/H9 -> 0 | S10: Food and Beverages | T10: =CORREL(P3:P30,J3:J30) -> 0.048366331 | U10: Very Week
A11: 2021-October | B11: 167.7 | C11: 164.2 | D11: 169.1 | E11: 155.7 | F11: 158.6 | G11: 163.9 | H11: 165.5 | I11: 83.54 | J11: =(B11-B10)/B10 -> 0.022560976 | K11: =(C11-C10)/C10 -> 0.0098400984 | L11: =(D11-D10)/D10 -> 0.0041567696 | M11: =(E11-E10)/E10 -> 0.011038961 | N11: =(F11-F10)/F10 -> 0.0057070387 | O11: =(G11-G10)/G10 -> 0.0012217471 | P11: =(I11-I10)/I10 -> 0.12149282 | Q11: =(H11-H10)/H10 -> 0.014093137 | S11: Fuel and Light | T11: =CORREL(P3:P30,K3:K30) -> 0.12569723 | U11: Very Week
A12: 2021-November | B12: 169.7 | C12: 163.9 | D12: 169.9 | E12: 154.8 | F12: 159.8 | G12: 164.3 | H12: 166.7 | I12: 81.05 | J12: =(B12-B11)/B11 -> 0.011926058 | K12: =(C12-C11)/C11 -> -0.0018270402 | L12: =(D12-D11)/D11 -> 0.0047309284 | M12: =(E12-E11)/E11 -> -0.0057803468 | N12: =(F12-F11)/F11 -> 0.0075662043 | O12: =(G12-G11)/G11 -> 0.0024405125 | P12: =(I12-I11)/I11 -> -0.029806081 | Q12: =(H12-H11)/H11 -> 0.0072507553 | S12: Recreation and amusement | T12: =CORREL(P3:P30,N3:N30) -> 0.12188552 | U12: Very Week
A13: 2021-December | B13: 168.2 | C13: 164.1 | D13: 170.6 | E13: 155.7 | F13: 160.6 | G13: 164.4 | H13: 166.2 | I13: 74.17 | J13: =(B13-B12)/B12 -> -0.0088391279 | K13: =(C13-C12)/C12 -> 0.0012202563 | L13: =(D13-D12)/D12 -> 0.0041200706 | M13: =(E13-E12)/E12 -> 0.0058139535 | N13: =(F13-F12)/F12 -> 0.0050062578 | O13: =(G13-G12)/G12 -> 0.00060864273 | P13: =(I13-I12)/I12 -> -0.084885873 | Q13: =(H13-H12)/H12 -> -0.0029994001 | S13: Health | T13: =CORREL(P3:P30,L3:L30) -> 0.071230618 | U13: Very Week
A14: 2022-January | B14: 166.4 | C14: 164.2 | D14: 171.4 | E14: 156.5 | F14: 161.2 | G14: 164.7 | H14: 165.7 | I14: 86.51 | J14: =(B14-B13)/B13 -> -0.010701546 | K14: =(C14-C13)/C13 -> 0.00060938452 | L14: =(D14-D13)/D13 -> 0.0046893318 | M14: =(E14-E13)/E13 -> 0.0051380861 | N14: =(F14-F13)/F13 -> 0.00373599 | O14: =(G14-G13)/G13 -> 0.0018248175 | P14: =(I14-I13)/I13 -> 0.16637454 | Q14: =(H14-H13)/H13 -> -0.0030084236 | S14: Transport and communication | T14: =CORREL(P3:P30,M3:M30) -> 0.076469917 | U14: Very Week
A15: 2022-February | B15: 166.2 | C15: 165.7 | D15: 172.2 | E15: 156.9 | F15: 162.1 | G15: 165.4 | H15: 166.1 | I15: 97.13 | J15: =(B15-B14)/B14 -> -0.0012019231 | K15: =(C15-C14)/C14 -> 0.009135201 | L15: =(D15-D14)/D14 -> 0.0046674446 | M15: =(E15-E14)/E14 -> 0.0025559105 | N15: =(F15-F14)/F14 -> 0.0055831266 | O15: =(G15-G14)/G14 -> 0.0042501518 | P15: =(I15-I14)/I14 -> 0.12276037 | Q15: =(H15-H14)/H14 -> 0.0024140012 | S15: Education | T15: =CORREL(P3:P30,O3:O30) -> -0.1115141 | U15: Very Week
A16: 2022-March | B16: 168.4 | C16: 167.2 | D16: 173 | E16: 157.9 | F16: 163.3 | G16: 166 | H16: 167.7 | I16: 117.25 | J16: =(B16-B15)/B15 -> 0.013237064 | K16: =(C16-C15)/C15 -> 0.0090525045 | L16: =(D16-D15)/D15 -> 0.0046457607 | M16: =(E16-E15)/E15 -> 0.0063734863 | N16: =(F16-F15)/F15 -> 0.0074028378 | O16: =(G16-G15)/G15 -> 0.0036275695 | P16: =(I16-I15)/I15 -> 0.20714506 | Q16: =(H16-H15)/H15 -> 0.0096327514
A17: 2022-April | B17: 170.8 | C17: 172.2 | D17: 174 | E17: 162.6 | F17: 164.4 | G17: 166.9 | H17: 170.1 | I17: 104.58 | J17: =(B17-B16)/B16 -> 0.014251781 | K17: =(C17-C16)/C16 -> 0.029904306 | L17: =(D17-D16)/D16 -> 0.0057803468 | M17: =(E17-E16)/E16 -> 0.029765674 | N17: =(F17-F16)/F16 -> 0.0067360686 | O17: =(G17-G16)/G16 -> 0.0054216867 | P17: =(I17-I16)/I16 -> -0.1080597 | Q17: =(H17-H16)/H16 -> 0.01431127
A18: 2022-May | B18: 173.3 | C18: 174.6 | D18: 174.8 | E18: 163 | F18: 165.1 | G18: 167.9 | H18: 171.7 | I18: 113.34 | J18: =(B18-B17)/B17 -> 0.014637002 | K18: =(C18-C17)/C17 -> 0.013937282 | L18: =(D18-D17)/D17 -> 0.0045977011 | M18: =(E18-E17)/E17 -> 0.0024600246 | N18: =(F18-F17)/F17 -> 0.0042579075 | O18: =(G18-G17)/G17 -> 0.0059916117 | P18: =(I18-I17)/I17 -> 0.083763626 | Q18: =(H18-H17)/H17 -> 0.0094062316
A19: 2022-June | B19: 174.9 | C19: 176 | D19: 175.4 | E19: 161.1 | F19: 165.8 | G19: 169 | H19: 172.6 | I19: 122.71 | J19: =(B19-B18)/B18 -> 0.0092325447 | K19: =(C19-C18)/C18 -> 0.0080183276 | L19: =(D19-D18)/D18 -> 0.0034324943 | M19: =(E19-E18)/E18 -> -0.011656442 | N19: =(F19-F18)/F18 -> 0.0042398546 | O19: =(G19-G18)/G18 -> 0.0065515188 | P19: =(I19-I18)/I18 -> 0.082671608 | Q19: =(H19-H18)/H18 -> 0.0052417006
A20: 2022-July | B20: 175 | C20: 179.6 | D20: 176.1 | E20: 161.6 | F20: 166.3 | G20: 171.4 | H20: 173.4 | I20: 111.93 | J20: =(B20-B19)/B19 -> 0.00057175529 | K20: =(C20-C19)/C19 -> 0.020454545 | L20: =(D20-D19)/D19 -> 0.003990878 | M20: =(E20-E19)/E19 -> 0.0031036623 | N20: =(F20-F19)/F19 -> 0.0030156815 | O20: =(G20-G19)/G19 -> 0.014201183 | P20: =(I20-I19)/I19 -> -0.087849401 | Q20: =(H20-H19)/H19 -> 0.0046349942 | S20: Key Insights
A21: 2022-August | B21: 176.3 | C21: 178.8 | D21: 176.8 | E21: 161.9 | F21: 166.9 | G21: 172.3 | H21: 174.3 | I21: 100.45 | J21: =(B21-B20)/B20 -> 0.0074285714 | K21: =(C21-C20)/C20 -> -0.004454343 | L21: =(D21-D20)/D20 -> 0.0039750142 | M21: =(E21-E20)/E20 -> 0.0018564356 | N21: =(F21-F20)/F20 -> 0.0036079375 | O21: =(G21-G20)/G20 -> 0.0052508751 | P21: =(I21-I20)/I20 -> -0.1025641 | Q21: =(H21-H20)/H20 -> 0.0051903114
A22: 2022-September | B22: 177.8 | C22: 179.5 | D22: 177.8 | E22: 162.3 | F22: 167.6 | G22: 173.1 | H22: 175.3 | I22: 89.76 | J22: =(B22-B21)/B21 -> 0.0085082246 | K22: =(C22-C21)/C21 -> 0.0039149888 | L22: =(D22-D21)/D21 -> 0.0056561086 | M22: =(E22-E21)/E21 -> 0.0024706609 | N22: =(F22-F21)/F21 -> 0.0041941282 | O22: =(G22-G21)/G21 -> 0.0046430644 | P22: =(I22-I21)/I21 -> -0.10642111 | Q22: =(H22-H21)/H21 -> 0.0057372347 | S22: Fuel and Light (0.13) has the highest positive correlation, followed closely by Recreation and Amusement (0.12).
A23: 2022-October | B23: 179.6 | C23: 180.5 | D23: 178.7 | E23: 162.9 | F23: 168.2 | G23: 173.4 | H23: 176.7 | I23: 93.33 | J23: =(B23-B22)/B22 -> 0.010123735 | K23: =(C23-C22)/C22 -> 0.0055710306 | L23: =(D23-D22)/D22 -> 0.0050618673 | M23: =(E23-E22)/E22 -> 0.0036968577 | N23: =(F23-F22)/F22 -> 0.0035799523 | O23: =(G23-G22)/G22 -> 0.0017331023 | P23: =(I23-I22)/I22 -> 0.039772727 | Q23: =(H23-H22)/H22 -> 0.0079863092
A24: 2022-November | B24: 178.3 | C24: 181.3 | D24: 179.8 | E24: 163 | F24: 168.5 | G24: 173.7 | H24: 176.5 | I24: 91.42 | J24: =(B24-B23)/B23 -> -0.0072383073 | K24: =(C24-C23)/C23 -> 0.004432133 | L24: =(D24-D23)/D23 -> 0.006155568 | M24: =(E24-E23)/E23 -> 0.00061387354 | N24: =(F24-F23)/F23 -> 0.001783591 | O24: =(G24-G23)/G23 -> 0.0017301038 | P24: =(I24-I23)/I23 -> -0.020465017 | Q24: =(H24-H23)/H23 -> -0.0011318619 | S24: Education (-0.11) is the only category with a negative correlation, indicating a very weak inverse relationship with crude oil price changes.
A25: 2022-December | B25: 175.9 | C25: 182 | D25: 181.1 | E25: 163.4 | F25: 168.9 | G25: 174.1 | H25: 175.7 | I25: 80.92 | J25: =(B25-B24)/B24 -> -0.01346046 | K25: =(C25-C24)/C24 -> 0.0038610039 | L25: =(D25-D24)/D24 -> 0.0072302558 | M25: =(E25-E24)/E24 -> 0.0024539877 | N25: =(F25-F24)/F24 -> 0.0023738872 | O25: =(G25-G24)/G24 -> 0.002302821 | P25: =(I25-I24)/I24 -> -0.11485452 | Q25: =(H25-H24)/H24 -> -0.0045325779
A26: 2023-January | B26: 176.7 | C26: 182 | D26: 182.3 | E26: 163.6 | F26: 169.5 | G26: 174.3 | H26: 176.5 | I26: 82.5 | J26: =(B26-B25)/B25 -> 0.0045480387 | K26: =(C26-C25)/C25 -> 0 | L26: =(D26-D25)/D25 -> 0.0066261734 | M26: =(E26-E25)/E25 -> 0.0012239902 | N26: =(F26-F25)/F25 -> 0.0035523979 | O26: =(G26-G25)/G25 -> 0.0011487651 | P26: =(I26-I25)/I25 -> 0.019525457 | Q26: =(H26-H25)/H25 -> 0.0045532157 | S26: Overall, crude oil price fluctuations do not show a strong relationship with the movement of these CPI categories during 2021–2023.
A27: 2023-February | B27: 177 | C27: 182.1 | D27: 184.4 | E27: 164.2 | F27: 170.3 | G27: 175 | H27: 177.2 | I27: 82.59 | J27: =(B27-B26)/B26 -> 0.0016977929 | K27: =(C27-C26)/C26 -> 0.00054945055 | L27: =(D27-D26)/D26 -> 0.011519473 | M27: =(E27-E26)/E26 -> 0.0036674817 | N27: =(F27-F26)/F26 -> 0.004719764 | O27: =(G27-G26)/G26 -> 0.0040160643 | P27: =(I27-I26)/I26 -> 0.0010909091 | Q27: =(H27-H26)/H26 -> 0.0039660057
A28: 2023-March | B28: 177 | C28: 181.9 | D28: 184.4 | E28: 164.2 | F28: 170.3 | G28: 175 | H28: 177.2 | I28: 78.43 | J28: =(B28-B27)/B27 -> 0 | K28: =(C28-C27)/C27 -> -0.0010982976 | L28: =(D28-D27)/D27 -> 0 | M28: =(E28-E27)/E27 -> 0 | N28: =(F28-F27)/F27 -> 0 | O28: =(G28-G27)/G27 -> 0 | P28: =(I28-I27)/I27 -> -0.050369294 | Q28: =(H28-H27)/H27 -> 0
A29: 2023-April | B29: 177.9 | C29: 181.7 | D29: 185 | E29: 164.5 | F29: 170.7 | G29: 176.4 | H29: 178.1 | I29: 84.64 | J29: =(B29-B28)/B28 -> 0.0050847458 | K29: =(C29-C28)/C28 -> -0.0010995052 | L29: =(D29-D28)/D28 -> 0.0032537961 | M29: =(E29-E28)/E28 -> 0.0018270402 | N29: =(F29-F28)/F28 -> 0.0023487962 | O29: =(G29-G28)/G28 -> 0.008 | P29: =(I29-I28)/I28 -> 0.079178886 | Q29: =(H29-H28)/H28 -> 0.0050790068
A30: 2023-May | B30: 179.1 | C30: 182.8 | D30: 185.7 | E30: 164.8 | F30: 171.2 | G30: 177.1 | H30: 179.1 | I30: 75.47 | J30: =(B30-B29)/B29 -> 0.0067453626 | K30: =(C30-C29)/C29 -> 0.0060539351 | L30: =(D30-D29)/D29 -> 0.0037837838 | M30: =(E30-E29)/E29 -> 0.0018237082 | N30: =(F30-F29)/F29 -> 0.0029291154 | O30: =(G30-G29)/G29 -> 0.003968254 | P30: =(I30-I29)/I29 -> -0.10834121 | Q30: =(H30-H29)/H29 -> 0.0056148231

Sheet Ques 5 Subategory
A1: Year | B1: Month | C1: Cereals and products | D1: Cereals and products MoM% | E1: Meat and fish | F1: Meat and ish MoM% | G1: Egg | H1: Egg MoM% | I1: Milk and products | J1: Milk and products MoM% | K1: Oils and fats | L1: Oils and fats MoM% | M1: Fruits | N1: Fruits MoM% | O1: Vegetables | P1: Vegetables MoM% | Q1: Pulses and products | R1: Pulses and products MoM% | S1: Sugar and Confectionery | T1: Sugar and Confectionery MoM% | U1: Spices | V1: Spices MoM% | W1: Non-alcoholic beverages | X1: Non-alcoholic beverages MoM% | Y1: Prepared meals, snacks, sweets etc. | Z1: Prepared meals, snacks, sweets etc. MoM% | AA1: Food and beverages | AB1: Food and beverages MoM% | AC1: Pan, tobacco and intoxicants | AD1: Pan, tobacco and intoxicants MoM% | AE1: Clothing | AF1: Clothing MoM% | AG1: Footwear | AH1: Footwear MoM% | AI1: Clothing and footwear | AJ1: Clothing and footwear MoM% | AK1: Housing | AL1: Housing MoM% | AM1: Fuel and light | AN1: Fuel and light MoM% | AO1: Household goods and services | AP1: Household goods and services MoM% | AQ1: Health | AR1: Health MoM% | AS1: Transport and communication | AT1: Transport and communication MoM% | AU1: Recreation and amusement | AV1: Recreation and amusement MoM% | AW1: Education | AX1: Education MoM% | AY1: Personal care and effects | AZ1: Personal care and effects MoM% | BA1: Miscellaneous | BB1: Miscellaneous MoM% | BC1: General index | BD1: General index MoM% | BE1: Crude Oil | BF1: Crude Oil MoM%
A2: 2021 | B2: January | C2: 144.9 | E2: 190.1 | G2: 175.3 | I2: 154.1 | K2: 150.9 | M2: 149.6 | O2: 194.2 | Q2: 160.4 | S2: 114.6 | U2: 164 | W2: 151.8 | Y2: 165.6 | AA2: 161 | AC2: 186.5 | AE2: 155.5 | AG2: 146.1 | AI2: 154.2 | AK2: 157.7 | AM2: 147.9 | AO2: 150 | AQ2: 159.3 | AS2: 141.9 | AU2: 149.6 | AW2: 159.2 | AY2: 156.8 | BA2: 151.9 | BC2: 157.3 | BE2: 54.77
A3: 2021 | B3: February | C3: 144.3 | D3: =(C3-C2)/C2 -> -0.0041407867 | E3: 186.5 | F3: =(E3-E2)/E2 -> -0.018937401 | G3: 168.7 | H3: =(G3-G2)/G2 -> -0.037649743 | I3: 154.7 | J3: =(I3-I2)/I2 -> 0.0038935756 | K3: 158.7 | L3: =(K3-K2)/K2 -> 0.051689861 | M3: 150.7 | N3: =(M3-M2)/M2 -> 0.0073529412 | O3: 160 | P3: =(O3-O2)/O2 -> -0.17610711 | Q3: 158.8 | R3: =(Q3-Q2)/Q2 -> -0.0099750623 | S3: 112.8 | T3: =(S3-S2)/S2 -> -0.015706806 | U3: 164.2 | V3: =(U3-U2)/U2 -> 0.0012195122 | W3: 155.5 | X3: =(W3-W2)/W2 -> 0.024374177 | Y3: 167.5 | Z3: =(Y3-Y2)/Y2 -> 0.01147343 | AA3: 156.9 | AB3: =(AA3-AA2)/AA2 -> -0.025465839 | AC3: 188.3 | AD3: =(AC3-AC2)/AC2 -> 0.0096514745 | AE3: 157.2 | AF3: =(AE3-AE2)/AE2 -> 0.010932476 | AG3: 147.4 | AH3: =(AG3-AG2)/AG2 -> 0.0088980151 | AI3: 155.8 | AJ3: =(AI3-AI2)/AI2 -> 0.010376135 | AK3: 159.8 | AL3: =(AK3-AK2)/AK2 -> 0.013316424 | AM3: 152.4 | AN3: =(AM3-AM2)/AM2 -> 0.030425963 | AO3: 150.9 | AP3: =(AO3-AO2)/AO2 -> 0.006 | AQ3: 161.3 | AR3: =(AQ3-AQ2)/AQ2 -> 0.012554928 | AS3: 145.1 | AT3: =(AS3-AS2)/AS2 -> 0.022551092 | AU3: 151.5 | AV3: =(AU3-AU2)/AU2 -> 0.012700535 | AW3: 159.5 | AX3: =(AW3-AW2)/AW2 -> 0.0018844221 | AY3: 155.8 | AZ3: =(AY3-AY2)/AY2 -> -0.006377551 | BA3: 153.4 | BB3: =(BA3-BA2)/BA2 -> 0.0098749177 | BC3: 156.6 | BD3: =(BC3-BC2)/BC2 -> -0.0044500954 | BE3: 62.28 | BF3: =(BE3-BE2)/BE2 -> 0.13711886 | BH3: Impact of Crude Oil Price Fluctuations on CPI Sub-Categories (Correlation Analysis: 2021–2023)
A4: 2021 | B4: March | C4: 144.1 | D4: =(C4-C3)/C3 -> -0.0013860014 | E4: 192.2 | F4: =(E4-E3)/E3 -> 0.030563003 | G4: 163.8 | H4: =(G4-G3)/G3 -> -0.029045643 | I4: 154.9 | J4: =(I4-I3)/I3 -> 0.0012928248 | K4: 163.9 | L4: =(K4-K3)/K3 -> 0.032766226 | M4: 153.7 | N4: =(M4-M3)/M3 -> 0.0199071 | O4: 149.5 | P4: =(O4-O3)/O3 -> -0.065625 | Q4: 159.8 | R4: =(Q4-Q3)/Q3 -> 0.0062972292 | S4: 112.6 | T4: =(S4-S3)/S3 -> -0.0017730496 | U4: 163.5 | V4: =(U4-U3)/U3 -> -0.0042630938 | W4: 156.5 | X4: =(W4-W3)/W3 -> 0.0064308682 | Y4: 168.2 | Z4: =(Y4-Y3)/Y3 -> 0.0041791045 | AA4: 156.7 | AB4: =(AA4-AA3)/AA3 -> -0.0012746973 | AC4: 188.1 | AD4: =(AC4-AC3)/AC3 -> -0.0010621349 | AE4: 157.8 | AF4: =(AE4-AE3)/AE3 -> 0.0038167939 | AG4: 147.9 | AH4: =(AG4-AG3)/AG3 -> 0.0033921303 | AI4: 156.4 | AJ4: =(AI4-AI3)/AI3 -> 0.0038510911 | AK4: 159.9 | AL4: =(AK4-AK3)/AK3 -> 0.00062578223 | AM4: 155.5 | AN4: =(AM4-AM3)/AM3 -> 0.020341207 | AO4: 151.2 | AP4: =(AO4-AO3)/AO3 -> 0.0019880716 | AQ4: 161.7 | AR4: =(AQ4-AQ3)/AQ3 -> 0.0024798512 | AS4: 146.2 | AT4: =(AS4-AS3)/AS3 -> 0.0075809786 | AU4: 152.6 | AV4: =(AU4-AU3)/AU3 -> 0.0072607261 | AW4: 160.2 | AX4: =(AW4-AW3)/AW3 -> 0.0043887147 | AY4: 153.8 | AZ4: =(AY4-AY3)/AY3 -> -0.01283697 | BA4: 153.8 | BB4: =(BA4-BA3)/BA3 -> 0.0026075619 | BC4: 156.8 | BD4: =(BC4-BC3)/BC3 -> 0.0012771392 | BE4: 65.41 | BF4: =(BE4-BE3)/BE3 -> 0.050256904
A5: 2021 | B5: April | C5: 144.3 | D5: =(C5-C4)/C4 -> 0.0013879251 | E5: 198 | F5: =(E5-E4)/E4 -> 0.030176899 | G5: 164.6 | H5: =(G5-G4)/G4 -> 0.0048840049 | I5: 155.4 | J5: =(I5-I4)/I4 -> 0.003227889 | K5: 170.1 | L5: =(K5-K4)/K4 -> 0.037827944 | M5: 164.4 | N5: =(M5-M4)/M4 -> 0.069616135 | O5: 144.1 | P5: =(O5-O4)/O4 -> -0.036120401 | Q5: 161.7 | R5: =(Q5-Q4)/Q4 -> 0.011889862 | S5: 113.1 | T5: =(S5-S4)/S4 -> 0.0044404973 | U5: 163.9 | V5: =(U5-U4)/U4 -> 0.0024464832 | W5: 157.6 | X5: =(W5-W4)/W4 -> 0.007028754 | Y5: 168.9 | Z5: =(Y5-Y4)/Y4 -> 0.0041617122 | AA5: 158 | AB5: =(AA5-AA4)/AA4 -> 0.0082961072 | AC5: 188.8 | AD5: =(AC5-AC4)/AC4 -> 0.0037214248 | AE5: 158.8 | AF5: =(AE5-AE4)/AE4 -> 0.0063371356 | AG5: 148.5 | AH5: =(AG5-AG4)/AG4 -> 0.0040567951 | AI5: 157.3 | AJ5: =(AI5-AI4)/AI4 -> 0.0057544757 | AK5: 161.4 | AL5: =(AK5-AK4)/AK4 -> 0.009380863 | AM5: 155.6 | AN5: =(AM5-AM4)/AM4 -> 0.00064308682 | AO5: 151.8 | AP5: =(AO5-AO4)/AO4 -> 0.003968254 | AQ5: 162.3 | AR5: =(AQ5-AQ4)/AQ4 -> 0.0037105751 | AS5: 146.6 | AT5: =(AS5-AS4)/AS4 -> 0.0027359781 | AU5: 153.2 | AV5: =(AU5-AU4)/AU4 -> 0.003931848 | AW5: 160.3 | AX5: =(AW5-AW4)/AW4 -> 0.00062421973 | AY5: 155.4 | AZ5: =(AY5-AY4)/AY4 -> 0.010403121 | BA5: 154.4 | BB5: =(BA5-BA4)/BA4 -> 0.0039011704 | BC5: 157.8 | BD5: =(BC5-BC4)/BC4 -> 0.006377551 | BE5: 64.81 | BF5: =(BE5-BE4)/BE4 -> -0.0091729093
A6: 2021 | B6: May | C6: 146.3 | D6: =(C6-C5)/C5 -> 0.013860014 | E6: 200.5 | F6: =(E6-E5)/E5 -> 0.012626263 | G6: 170.3 | H6: =(G6-G5)/G5 -> 0.034629405 | I6: 156.1 | J6: =(I6-I5)/I5 -> 0.0045045045 | K6: 178.7 | L6: =(K6-K5)/K5 -> 0.050558495 | M6: 167.1 | N6: =(M6-M5)/M5 -> 0.016423358 | O6: 147.9 | P6: =(O6-O5)/O5 -> 0.026370576 | Q6: 165.4 | R6: =(Q6-Q5)/Q5 -> 0.02288188 | S6: 114.8 | T6: =(S6-S5)/S5 -> 0.015030946 | U6: 168.2 | V6: =(U6-U5)/U5 -> 0.026235509 | W6: 159.3 | X6: =(W6-W5)/W5 -> 0.010786802 | Y6: 170.4 | Z6: =(Y6-Y5)/Y5 -> 0.0088809947 | AA6: 160.7 | AB6: =(AA6-AA5)/AA5 -> 0.017088608 | AC6: 191.9 | AD6: =(AC6-AC5)/AC5 -> 0.016419492 | AE6: 161.8 | AF6: =(AE6-AE5)/AE5 -> 0.018891688 | AG6: 152.1 | AH6: =(AG6-AG5)/AG5 -> 0.024242424 | AI6: 160.4 | AJ6: =(AI6-AI5)/AI5 -> 0.019707565 | AK6: 161.6 | AL6: =(AK6-AK5)/AK5 -> 0.0012391574 | AM6: 159.4 | AN6: =(AM6-AM5)/AM5 -> 0.024421594 | AO6: 154.7 | AP6: =(AO6-AO5)/AO5 -> 0.019104084 | AQ6: 165.8 | AR6: =(AQ6-AQ5)/AQ5 -> 0.021565003 | AS6: 148.9 | AT6: =(AS6-AS5)/AS5 -> 0.01568895 | AU6: 155.8 | AV6: =(AU6-AU5)/AU5 -> 0.016971279 | AW6: 161.2 | AX6: =(AW6-AW5)/AW5 -> 0.0056144729 | AY6: 158.6 | AZ6: =(AY6-AY5)/AY5 -> 0.020592021 | BA6: 156.8 | BB6: =(BA6-BA5)/BA5 -> 0.015544041 | BC6: 160.4 | BD6: =(BC6-BC5)/BC5 -> 0.016476553 | BE6: 68.53 | BF6: =(BE6-BE5)/BE5 -> 0.05739855
A7: 2021 | B7: June | C7: 146.7 | D7: =(C7-C6)/C6 -> 0.002734108 | E7: 202 | F7: =(E7-E6)/E6 -> 0.0074812968 | G7: 180.7 | H7: =(G7-G6)/G6 -> 0.061068702 | I7: 156.2 | J7: =(I7-I6)/I6 -> 0.00064061499 | K7: 183.7 | L7: =(K7-K6)/K6 -> 0.027979855 | M7: 164.6 | N7: =(M7-M6)/M6 -> -0.014961101 | O7: 155.4 | P7: =(O7-O6)/O6 -> 0.050709939 | Q7: 166 | R7: =(Q7-Q6)/Q6 -> 0.0036275695 | S7: 115.1 | T7: =(S7-S6)/S6 -> 0.0026132404 | U7: 168.5 | V7: =(U7-U6)/U6 -> 0.001783591 | W7: 160 | X7: =(W7-W6)/W6 -> 0.0043942247 | Y7: 172.4 | Z7: =(Y7-Y6)/Y6 -> 0.011737089 | AA7: 162.6 | AB7: =(AA7-AA6)/AA6 -> 0.011823273 | AC7: 190.8 | AD7: =(AC7-AC6)/AC6 -> -0.0057321522 | AE7: 162.2 | AF7: =(AE7-AE6)/AE6 -> 0.0024721879 | AG7: 151.8 | AH7: =(AG7-AG6)/AG6 -> -0.0019723866 | AI7: 160.7 | AJ7: =(AI7-AI6)/AI6 -> 0.0018703242 | AK7: 160.5 | AL7: =(AK7-AK6)/AK6 -> -0.0068069307 | AM7: 159.8 | AN7: =(AM7-AM6)/AM6 -> 0.0025094103 | AO7: 154.8 | AP7: =(AO7-AO6)/AO6 -> 0.00064641241 | AQ7: 166.3 | AR7: =(AQ7-AQ6)/AQ6 -> 0.0030156815 | AS7: 150.7 | AT7: =(AS7-AS6)/AS6 -> 0.01208865 | AU7: 154.9 | AV7: =(AU7-AU6)/AU6 -> -0.0057766367 | AW7: 161.7 | AX7: =(AW7-AW6)/AW6 -> 0.003101737 | AY7: 158.8 | AZ7: =(AY7-AY6)/AY6 -> 0.001261034 | BA7: 157.6 | BB7: =(BA7-BA6)/BA6 -> 0.0051020408 | BC7: 161.3 | BD7: =(BC7-BC6)/BC6 -> 0.0056109726 | BE7: 73.16 | BF7: =(BE7-BE6)/BE6 -> 0.067561652
A8: 2021 | B8: July | C8: 146.4 | D8: =(C8-C7)/C7 -> -0.0020449898 | E8: 206.8 | F8: =(E8-E7)/E7 -> 0.023762376 | G8: 182.2 | H8: =(G8-G7)/G7 -> 0.0083010515 | I8: 157.5 | J8: =(I8-I7)/I7 -> 0.0083226633 | K8: 182.1 | L8: =(K8-K7)/K7 -> -0.008709853 | M8: 163.9 | N8: =(M8-M7)/M7 -> -0.0042527339 | O8: 164.2 | P8: =(O8-O7)/O7 -> 0.056628057 | Q8: 164 | R8: =(Q8-Q7)/Q7 -> -0.012048193 | S8: 114.5 | T8: =(S8-S7)/S7 -> -0.0052128584 | U8: 168.3 | V8: =(U8-U7)/U7 -> -0.0011869436 | W8: 160.9 | X8: =(W8-W7)/W7 -> 0.005625 | Y8: 172.2 | Z8: =(Y8-Y7)/Y7 -> -0.0011600928 | AA8: 164 | AB8: =(AA8-AA7)/AA7 -> 0.0086100861 | AC8: 191.2 | AD8: =(AC8-AC7)/AC7 -> 0.0020964361 | AE8: 162.8 | AF8: =(AE8-AE7)/AE7 -> 0.0036991369 | AG8: 153.1 | AH8: =(AG8-AG7)/AG7 -> 0.0085638999 | AI8: 161.4 | AJ8: =(AI8-AI7)/AI7 -> 0.0043559428 | AK8: 161.5 | AL8: =(AK8-AK7)/AK7 -> 0.0062305296 | AM8: 160.7 | AN8: =(AM8-AM7)/AM7 -> 0.0056320401 | AO8: 155.8 | AP8: =(AO8-AO7)/AO7 -> 0.0064599483 | AQ8: 167 | AR8: =(AQ8-AQ7)/AQ7 -> 0.0042092604 | AS8: 153.1 | AT8: =(AS8-AS7)/AS7 -> 0.01592568 | AU8: 155.3 | AV8: =(AU8-AU7)/AU7 -> 0.0025823112 | AW8: 163.2 | AX8: =(AW8-AW7)/AW7 -> 0.0092764378 | AY8: 160.1 | AZ8: =(AY8-AY7)/AY7 -> 0.008186398 | BA8: 159 | BB8: =(BA8-BA7)/BA7 -> 0.0088832487 | BC8: 162.5 | BD8: =(BC8-BC7)/BC7 -> 0.0074395536 | BE8: 75.17 | BF8: =(BE8-BE7)/BE7 -> 0.02747403 | BH8: Sub-Category | BI8: Correlation with Crude Oil MoM % | BJ8: Strength
